Exception in thread Exception in thread Thread-1:
Thread-1:
Traceback (most recent call last):
Traceback (most recent call last):
  File "/usr/lib/python3.8/threading.py", line 932, in _bootstrap_inner
  File "/usr/lib/python3.8/threading.py", line 932, in _bootstrap_inner
Exception in thread Thread-1:
Traceback (most recent call last):
  File "/usr/lib/python3.8/threading.py", line 932, in _bootstrap_inner
    self.run()
  File "/opt/bench/erpnext/env/lib/python3.8/site-packages/redis/client.py", line 3718, in run
    self.run()
  File "/opt/bench/erpnext/env/lib/python3.8/site-packages/redis/client.py", line 3718, in run
    self.run()
  File "/opt/bench/erpnext/env/lib/python3.8/site-packages/redis/client.py", line 3718, in run
    pubsub.get_message(ignore_subscribe_messages=True,
  File "/opt/bench/erpnext/env/lib/python3.8/site-packages/redis/client.py", line 3617, in get_message
    response = self.parse_response(block=False, timeout=timeout)
  File "/opt/bench/erpnext/env/lib/python3.8/site-packages/redis/client.py", line 3503, in parse_response
    if not block and not conn.can_read(timeout=timeout):
  File "/opt/bench/erpnext/env/lib/python3.8/site-packages/redis/connection.py", line 734, in can_read
    pubsub.get_message(ignore_subscribe_messages=True,
  File "/opt/bench/erpnext/env/lib/python3.8/site-packages/redis/client.py", line 3617, in get_message
    response = self.parse_response(block=False, timeout=timeout)
  File "/opt/bench/erpnext/env/lib/python3.8/site-packages/redis/client.py", line 3503, in parse_response
    if not block and not conn.can_read(timeout=timeout):
  File "/opt/bench/erpnext/env/lib/python3.8/site-packages/redis/connection.py", line 734, in can_read
    pubsub.get_message(ignore_subscribe_messages=True,
  File "/opt/bench/erpnext/env/lib/python3.8/site-packages/redis/client.py", line 3617, in get_message
    response = self.parse_response(block=False, timeout=timeout)
  File "/opt/bench/erpnext/env/lib/python3.8/site-packages/redis/client.py", line 3503, in parse_response
    if not block and not conn.can_read(timeout=timeout):
  File "/opt/bench/erpnext/env/lib/python3.8/site-packages/redis/connection.py", line 734, in can_read
    return self._parser.can_read(timeout)
  File "/opt/bench/erpnext/env/lib/python3.8/site-packages/redis/connection.py", line 321, in can_read
    return self._buffer and self._buffer.can_read(timeout)
  File "/opt/bench/erpnext/env/lib/python3.8/site-packages/redis/connection.py", line 230, in can_read
    self._read_from_socket(timeout=timeout,
  File "/opt/bench/erpnext/env/lib/python3.8/site-packages/redis/connection.py", line 201, in _read_from_socket
    raise ConnectionError(SERVER_CLOSED_CONNECTION_ERROR)
redis.exceptions.ConnectionError: Connection closed by server.
    return self._parser.can_read(timeout)
  File "/opt/bench/erpnext/env/lib/python3.8/site-packages/redis/connection.py", line 321, in can_read
    return self._buffer and self._buffer.can_read(timeout)
  File "/opt/bench/erpnext/env/lib/python3.8/site-packages/redis/connection.py", line 230, in can_read
    self._read_from_socket(timeout=timeout,
  File "/opt/bench/erpnext/env/lib/python3.8/site-packages/redis/connection.py", line 201, in _read_from_socket
    raise ConnectionError(SERVER_CLOSED_CONNECTION_ERROR)
redis.exceptions.ConnectionError: Connection closed by server.
    return self._parser.can_read(timeout)
  File "/opt/bench/erpnext/env/lib/python3.8/site-packages/redis/connection.py", line 321, in can_read
    return self._buffer and self._buffer.can_read(timeout)
  File "/opt/bench/erpnext/env/lib/python3.8/site-packages/redis/connection.py", line 230, in can_read
    self._read_from_socket(timeout=timeout,
  File "/opt/bench/erpnext/env/lib/python3.8/site-packages/redis/connection.py", line 201, in _read_from_socket
    raise ConnectionError(SERVER_CLOSED_CONNECTION_ERROR)
redis.exceptions.ConnectionError: Connection closed by server.
Traceback (most recent call last):
  File "/opt/bench/erpnext/env/lib/python3.8/site-packages/redis/connection.py", line 559, in connect
Exception in thread Thread-1:
Traceback (most recent call last):
  File "/usr/lib/python3.8/threading.py", line 932, in _bootstrap_inner
    self.run()
  File "/opt/bench/erpnext/env/lib/python3.8/site-packages/redis/client.py", line 3718, in run
    pubsub.get_message(ignore_subscribe_messages=True,
  File "/opt/bench/erpnext/env/lib/python3.8/site-packages/redis/client.py", line 3617, in get_message
Traceback (most recent call last):
  File "/opt/bench/erpnext/env/lib/python3.8/site-packages/redis/connection.py", line 559, in connect
    response = self.parse_response(block=False, timeout=timeout)
  File "/opt/bench/erpnext/env/lib/python3.8/site-packages/redis/client.py", line 3503, in parse_response
    sock = self._connect()
  File "/opt/bench/erpnext/env/lib/python3.8/site-packages/redis/connection.py", line 615, in _connect
    raise err
  File "/opt/bench/erpnext/env/lib/python3.8/site-packages/redis/connection.py", line 603, in _connect
    sock.connect(socket_address)
OSError    : if not block and not conn.can_read(timeout=timeout):[Errno 99] Cannot assign requested address

  File "/opt/bench/erpnext/env/lib/python3.8/site-packages/redis/connection.py", line 734, in can_read

During handling of the above exception, another exception occurred:

Traceback (most recent call last):
  File "/usr/lib/python3.8/runpy.py", line 194, in _run_module_as_main
    return _run_code(code, main_globals, None,    
return self._parser.can_read(timeout)  File "/usr/lib/python3.8/runpy.py", line 87, in _run_code

  File "/opt/bench/erpnext/env/lib/python3.8/site-packages/redis/connection.py", line 321, in can_read
        exec(code, run_globals)return self._buffer and self._buffer.can_read(timeout)

  File "/opt/bench/erpnext/env/lib/python3.8/site-packages/redis/connection.py", line 230, in can_read
  File "/opt/bench/erpnext/apps/frappe/frappe/utils/bench_helper.py", line 104, in <module>
    self._read_from_socket(timeout=timeout,
  File "/opt/bench/erpnext/env/lib/python3.8/site-packages/redis/connection.py", line 201, in _read_from_socket
    raise ConnectionError(SERVER_CLOSED_CONNECTION_ERROR)
    main()
  File "/opt/bench/erpnext/apps/frappe/frappe/utils/bench_helper.py", line 18, in main
redis.exceptions.ConnectionError: Connection closed by server.
    click.Group(commands=commands)(prog_name='bench')
  File "/opt/bench/erpnext/env/lib/python3.8/site-packages/click/core.py", line 829, in __call__
    sock = self._connect()
  File "/opt/bench/erpnext/env/lib/python3.8/site-packages/redis/connection.py", line 615, in _connect
    return self.main(*args, **kwargs)
  File "/opt/bench/erpnext/env/lib/python3.8/site-packages/click/core.py", line 782, in main
    raise err
  File "/opt/bench/erpnext/env/lib/python3.8/site-packages/redis/connection.py", line 603, in _connect
    sock.connect(socket_address)
    rv = self.invoke(ctx)
OSError  File "/opt/bench/erpnext/env/lib/python3.8/site-packages/click/core.py", line 1259, in invoke
: [Errno 99] Cannot assign requested address

During handling of the above exception, another exception occurred:

Traceback (most recent call last):
  File "/usr/lib/python3.8/runpy.py", line 194, in _run_module_as_main
    return _run_code(code, main_globals, None,
  File "/usr/lib/python3.8/runpy.py", line 87, in _run_code
    exec(code, run_globals)
  File "/opt/bench/erpnext/apps/frappe/frappe/utils/bench_helper.py", line 104, in <module>
    main()
  File "/opt/bench/erpnext/apps/frappe/frappe/utils/bench_helper.py", line 18, in main
    click.Group(commands=commands)(prog_name='bench')
  File "/opt/bench/erpnext/env/lib/python3.8/site-packages/click/core.py", line 829, in __call__
    return _process_result(sub_ctx.command.invoke(sub_ctx))
  File "/opt/bench/erpnext/env/lib/python3.8/site-packages/click/core.py", line 1259, in invoke
    return self.main(*args, **kwargs)
  File "/opt/bench/erpnext/env/lib/python3.8/site-packages/click/core.py", line 782, in main
    return _process_result(sub_ctx.command.invoke(sub_ctx))
  File "/opt/bench/erpnext/env/lib/python3.8/site-packages/click/core.py", line 1066, in invoke
    rv = self.invoke(ctx)
  File "/opt/bench/erpnext/env/lib/python3.8/site-packages/click/core.py", line 1259, in invoke
    return ctx.invoke(self.callback, **ctx.params)
      File "/opt/bench/erpnext/env/lib/python3.8/site-packages/click/core.py", line 610, in invoke
return _process_result(sub_ctx.command.invoke(sub_ctx))
  File "/opt/bench/erpnext/env/lib/python3.8/site-packages/click/core.py", line 1259, in invoke
    return callback(*args, **kwargs)
  File "/opt/bench/erpnext/apps/frappe/frappe/commands/scheduler.py", line 181, in start_worker
    start_worker(queue, quiet = quiet, rq_username=rq_username, rq_password=rq_password)
  File "/opt/bench/erpnext/apps/frappe/frappe/utils/background_jobs.py", line 158, in start_worker
    return _process_result(sub_ctx.command.invoke(sub_ctx))
  File "/opt/bench/erpnext/env/lib/python3.8/site-packages/click/core.py", line 1066, in invoke
    Worker(queues, name=get_worker_name(queue_name)).work(logging_level = logging_level)
  File "/opt/bench/erpnext/env/lib/python3.8/site-packages/rq/worker.py", line 626, in work
    return ctx.invoke(self.callback, **ctx.params)
  File "/opt/bench/erpnext/env/lib/python3.8/site-packages/click/core.py", line 610, in invoke
    return callback(*args, **kwargs)
  File "/opt/bench/erpnext/apps/frappe/frappe/commands/scheduler.py", line 181, in start_worker
    start_worker(queue, quiet = quiet, rq_username=rq_username, rq_password=rq_password)
  File "/opt/bench/erpnext/apps/frappe/frappe/utils/background_jobs.py", line 158, in start_worker
    Worker(queues, name=get_worker_name(queue_name)).work(logging_level = logging_level)
  File "/opt/bench/erpnext/env/lib/python3.8/site-packages/rq/worker.py", line 626, in work
    self.register_death()
  File "/opt/bench/erpnext/env/lib/python3.8/site-packages/rq/worker.py", line 326, in register_death
    p.execute()
  File "/opt/bench/erpnext/env/lib/python3.8/site-packages/redis/client.py", line 4012, in execute
Traceback (most recent call last):
    conn = self.connection_pool.get_connection('MULTI',
  File "/opt/bench/erpnext/env/lib/python3.8/site-packages/redis/connection.py", line 1192, in get_connection
Exception in thread Thread-1:
Traceback (most recent call last):
  File "/usr/lib/python3.8/threading.py", line 932, in _bootstrap_inner
    connection.connect()
  File "/opt/bench/erpnext/env/lib/python3.8/site-packages/redis/connection.py", line 563, in connect
    raise ConnectionError(self._error_message(e))
redis.exceptions.ConnectionError: Error 99 connecting to localhost:11000. Cannot assign requested address.
    self.run()
  File "/opt/bench/erpnext/env/lib/python3.8/site-packages/redis/client.py", line 3718, in run
    pubsub.get_message(ignore_subscribe_messages=True,
  File "/opt/bench/erpnext/env/lib/python3.8/site-packages/redis/client.py", line 3617, in get_message
    response = self.parse_response(block=False, timeout=timeout)
  File "/opt/bench/erpnext/env/lib/python3.8/site-packages/redis/client.py", line 3503, in parse_response
    if not block and not conn.can_read(timeout=timeout):
  File "/opt/bench/erpnext/env/lib/python3.8/site-packages/redis/connection.py", line 734, in can_read
    return self._parser.can_read(timeout)
  File "/opt/bench/erpnext/env/lib/python3.8/site-packages/redis/connection.py", line 321, in can_read
    return self._buffer and self._buffer.can_read(timeout)
  File "/opt/bench/erpnext/env/lib/python3.8/site-packages/redis/connection.py", line 230, in can_read
    self._read_from_socket(timeout=timeout,
  File "/opt/bench/erpnext/env/lib/python3.8/site-packages/redis/connection.py", line 201, in _read_from_socket
    raise ConnectionError(SERVER_CLOSED_CONNECTION_ERROR)
redis.exceptions.ConnectionError: Connection closed by server.
  File "/opt/bench/erpnext/env/lib/python3.8/site-packages/redis/connection.py", line 559, in connect
    sock = self._connect()
  File "/opt/bench/erpnext/env/lib/python3.8/site-packages/redis/connection.py", line 615, in _connect
    raise err
  File "/opt/bench/erpnext/env/lib/python3.8/site-packages/redis/connection.py", line 603, in _connect
    sock.connect(socket_address)
OSError: [Errno 99] Cannot assign requested address

During handling of the above exception, another exception occurred:

Traceback (most recent call last):
  File "/usr/lib/python3.8/runpy.py", line 194, in _run_module_as_main
    return _run_code(code, main_globals, None,
  File "/usr/lib/python3.8/runpy.py", line 87, in _run_code
    exec(code, run_globals)
  File "/opt/bench/erpnext/apps/frappe/frappe/utils/bench_helper.py", line 104, in <module>
    main()
  File "/opt/bench/erpnext/apps/frappe/frappe/utils/bench_helper.py", line 18, in main
    click.Group(commands=commands)(prog_name='bench')
  File "/opt/bench/erpnext/env/lib/python3.8/site-packages/click/core.py", line 829, in __call__
    return self.main(*args, **kwargs)
  File "/opt/bench/erpnext/env/lib/python3.8/site-packages/click/core.py", line 782, in main
    rv = self.invoke(ctx)
  File "/opt/bench/erpnext/env/lib/python3.8/site-packages/click/core.py", line 1259, in invoke
Exception in thread     return _process_result(sub_ctx.command.invoke(sub_ctx))
  File "/opt/bench/erpnext/env/lib/python3.8/site-packages/click/core.py", line 1259, in invoke
Thread-1:
Traceback (most recent call last):
  File "/usr/lib/python3.8/threading.py", line 932, in _bootstrap_inner
    return _process_result(sub_ctx.command.invoke(sub_ctx))
  File "/opt/bench/erpnext/env/lib/python3.8/site-packages/click/core.py", line 1066, in invoke
    self.run()
  File "/opt/bench/erpnext/env/lib/python3.8/site-packages/redis/client.py", line 3718, in run
    return ctx.invoke(self.callback, **ctx.params)
  File "/opt/bench/erpnext/env/lib/python3.8/site-packages/click/core.py", line 610, in invoke
    return callback(*args, **kwargs)
  File "/opt/bench/erpnext/apps/frappe/frappe/commands/scheduler.py", line 181, in start_worker
    start_worker(queue, quiet = quiet, rq_username=rq_username, rq_password=rq_password)
  File "/opt/bench/erpnext/apps/frappe/frappe/utils/background_jobs.py", line 158, in start_worker
    Worker(queues, name=get_worker_name(queue_name)).work(logging_level = logging_level)
  File "/opt/bench/erpnext/env/lib/python3.8/site-packages/rq/worker.py", line 626, in work
    self.register_death()
  File "/opt/bench/erpnext/env/lib/python3.8/site-packages/rq/worker.py", line 326, in register_death
    pubsub.get_message(ignore_subscribe_messages=True,
      File "/opt/bench/erpnext/env/lib/python3.8/site-packages/redis/client.py", line 3617, in get_message
p.execute()
  File "/opt/bench/erpnext/env/lib/python3.8/site-packages/redis/client.py", line 4012, in execute
    response = self.parse_response(block=False, timeout=timeout)
  File "/opt/bench/erpnext/env/lib/python3.8/site-packages/redis/client.py", line 3503, in parse_response
    conn = self.connection_pool.get_connection('MULTI',
  File "/opt/bench/erpnext/env/lib/python3.8/site-packages/redis/connection.py", line 1192, in get_connection
    connection.connect()
  File "/opt/bench/erpnext/env/lib/python3.8/site-packages/redis/connection.py", line 563, in connect
    raise ConnectionError(self._error_message(e))
redis.exceptions.ConnectionError: Error 99 connecting to localhost:11000. Cannot assign requested address.
    if not block and not conn.can_read(timeout=timeout):
  File "/opt/bench/erpnext/env/lib/python3.8/site-packages/redis/connection.py", line 734, in can_read
    return self._parser.can_read(timeout)
  File "/opt/bench/erpnext/env/lib/python3.8/site-packages/redis/connection.py", line 321, in can_read
    return self._buffer and self._buffer.can_read(timeout)
  File "/opt/bench/erpnext/env/lib/python3.8/site-packages/redis/connection.py", line 230, in can_read
    self._read_from_socket(timeout=timeout,
  File "/opt/bench/erpnext/env/lib/python3.8/site-packages/redis/connection.py", line 201, in _read_from_socket
    raise ConnectionError(SERVER_CLOSED_CONNECTION_ERROR)
redis.exceptions.ConnectionError: Connection closed by server.
    self.register_death()
  File "/opt/bench/erpnext/env/lib/python3.8/site-packages/rq/worker.py", line 326, in register_death
    p.execute()
  File "/opt/bench/erpnext/env/lib/python3.8/site-packages/redis/client.py", line 4012, in execute
    conn = self.connection_pool.get_connection('MULTI',
  File "/opt/bench/erpnext/env/lib/python3.8/site-packages/redis/connection.py", line 1192, in get_connection
    connection.connect()
  File "/opt/bench/erpnext/env/lib/python3.8/site-packages/redis/connection.py", line 563, in connect
    raise ConnectionError(self._error_message(e))
redis.exceptions.ConnectionError: Error 99 connecting to localhost:11000. Cannot assign requested address.
01:31:52 Traceback (most recent call last):
  File "/opt/bench/erpnext/env/lib/python3.8/site-packages/rq/worker.py", line 1013, in perform_job
    rv = job.perform()
  File "/opt/bench/erpnext/env/lib/python3.8/site-packages/rq/job.py", line 709, in perform
    self._result = self._execute()
  File "/opt/bench/erpnext/env/lib/python3.8/site-packages/rq/job.py", line 732, in _execute
    result = self.func(*self.args, **self.kwargs)
  File "/opt/bench/erpnext/apps/frappe/frappe/utils/background_jobs.py", line 106, in execute_job
    method(**kwargs)
  File "/opt/bench/erpnext/apps/frappe/frappe/core/doctype/user/user.py", line 998, in create_contact
    contact.insert(ignore_permissions=True, ignore_links=ignore_links, ignore_mandatory=ignore_mandatory)
  File "/opt/bench/erpnext/apps/frappe/frappe/model/document.py", line 229, in insert
    self._validate_links()
  File "/opt/bench/erpnext/apps/frappe/frappe/model/document.py", line 827, in _validate_links
    frappe.throw(_("Could not find {0}").format(msg),
  File "/opt/bench/erpnext/apps/frappe/frappe/__init__.py", line 443, in throw
    msgprint(msg, raise_exception=exc, title=title, indicator='red', is_minimizable=is_minimizable, wide=wide, as_list=as_list)
  File "/opt/bench/erpnext/apps/frappe/frappe/__init__.py", line 422, in msgprint
    _raise_exception()
  File "/opt/bench/erpnext/apps/frappe/frappe/__init__.py", line 376, in _raise_exception
    raise raise_exception(msg)
frappe.exceptions.LinkValidationError: Could not find User Id: khoi345@gmail.com

01:31:52 Traceback (most recent call last):
  File "/opt/bench/erpnext/env/lib/python3.8/site-packages/rq/worker.py", line 1013, in perform_job
    rv = job.perform()
  File "/opt/bench/erpnext/env/lib/python3.8/site-packages/rq/job.py", line 709, in perform
    self._result = self._execute()
  File "/opt/bench/erpnext/env/lib/python3.8/site-packages/rq/job.py", line 732, in _execute
    result = self.func(*self.args, **self.kwargs)
  File "/opt/bench/erpnext/apps/frappe/frappe/utils/background_jobs.py", line 106, in execute_job
    method(**kwargs)
  File "/opt/bench/erpnext/apps/frappe/frappe/core/doctype/user/user.py", line 998, in create_contact
    contact.insert(ignore_permissions=True, ignore_links=ignore_links, ignore_mandatory=ignore_mandatory)
  File "/opt/bench/erpnext/apps/frappe/frappe/model/document.py", line 229, in insert
    self._validate_links()
  File "/opt/bench/erpnext/apps/frappe/frappe/model/document.py", line 827, in _validate_links
    frappe.throw(_("Could not find {0}").format(msg),
  File "/opt/bench/erpnext/apps/frappe/frappe/__init__.py", line 443, in throw
    msgprint(msg, raise_exception=exc, title=title, indicator='red', is_minimizable=is_minimizable, wide=wide, as_list=as_list)
  File "/opt/bench/erpnext/apps/frappe/frappe/__init__.py", line 422, in msgprint
    _raise_exception()
  File "/opt/bench/erpnext/apps/frappe/frappe/__init__.py", line 376, in _raise_exception
    raise raise_exception(msg)
frappe.exceptions.LinkValidationError: Could not find User Id: khoi345@gmail.com

08:46:05 Traceback (most recent call last):
  File "/opt/bench/erpnext/env/lib/python3.8/site-packages/rq/worker.py", line 1013, in perform_job
    rv = job.perform()
  File "/opt/bench/erpnext/env/lib/python3.8/site-packages/rq/job.py", line 709, in perform
    self._result = self._execute()
  File "/opt/bench/erpnext/env/lib/python3.8/site-packages/rq/job.py", line 732, in _execute
    result = self.func(*self.args, **self.kwargs)
  File "/opt/bench/erpnext/apps/frappe/frappe/utils/background_jobs.py", line 106, in execute_job
    method(**kwargs)
  File "/opt/bench/erpnext/apps/frappe/frappe/core/doctype/user/user.py", line 998, in create_contact
    contact.insert(ignore_permissions=True, ignore_links=ignore_links, ignore_mandatory=ignore_mandatory)
  File "/opt/bench/erpnext/apps/frappe/frappe/model/document.py", line 229, in insert
    self._validate_links()
  File "/opt/bench/erpnext/apps/frappe/frappe/model/document.py", line 827, in _validate_links
    frappe.throw(_("Could not find {0}").format(msg),
  File "/opt/bench/erpnext/apps/frappe/frappe/__init__.py", line 443, in throw
    msgprint(msg, raise_exception=exc, title=title, indicator='red', is_minimizable=is_minimizable, wide=wide, as_list=as_list)
  File "/opt/bench/erpnext/apps/frappe/frappe/__init__.py", line 422, in msgprint
    _raise_exception()
  File "/opt/bench/erpnext/apps/frappe/frappe/__init__.py", line 376, in _raise_exception
    raise raise_exception(msg)
frappe.exceptions.LinkValidationError: Could not find User Id: hoitv@draco.com.vn

09:08:57 Traceback (most recent call last):
  File "/opt/bench/erpnext/env/lib/python3.8/site-packages/rq/worker.py", line 1013, in perform_job
    rv = job.perform()
  File "/opt/bench/erpnext/env/lib/python3.8/site-packages/rq/job.py", line 709, in perform
    self._result = self._execute()
  File "/opt/bench/erpnext/env/lib/python3.8/site-packages/rq/job.py", line 732, in _execute
    result = self.func(*self.args, **self.kwargs)
  File "/opt/bench/erpnext/apps/frappe/frappe/utils/background_jobs.py", line 106, in execute_job
    method(**kwargs)
  File "/opt/bench/erpnext/apps/frappe/frappe/core/doctype/user/user.py", line 998, in create_contact
    contact.insert(ignore_permissions=True, ignore_links=ignore_links, ignore_mandatory=ignore_mandatory)
  File "/opt/bench/erpnext/apps/frappe/frappe/model/document.py", line 229, in insert
    self._validate_links()
  File "/opt/bench/erpnext/apps/frappe/frappe/model/document.py", line 827, in _validate_links
    frappe.throw(_("Could not find {0}").format(msg),
  File "/opt/bench/erpnext/apps/frappe/frappe/__init__.py", line 443, in throw
    msgprint(msg, raise_exception=exc, title=title, indicator='red', is_minimizable=is_minimizable, wide=wide, as_list=as_list)
  File "/opt/bench/erpnext/apps/frappe/frappe/__init__.py", line 422, in msgprint
    _raise_exception()
  File "/opt/bench/erpnext/apps/frappe/frappe/__init__.py", line 376, in _raise_exception
    raise raise_exception(msg)
frappe.exceptions.LinkValidationError: Could not find User Id: longtt@draco.biz

14:28:02 Traceback (most recent call last):
  File "/opt/bench/erpnext/env/lib/python3.8/site-packages/rq/worker.py", line 1013, in perform_job
    rv = job.perform()
  File "/opt/bench/erpnext/env/lib/python3.8/site-packages/rq/job.py", line 709, in perform
    self._result = self._execute()
  File "/opt/bench/erpnext/env/lib/python3.8/site-packages/rq/job.py", line 732, in _execute
    result = self.func(*self.args, **self.kwargs)
  File "/opt/bench/erpnext/apps/frappe/frappe/utils/background_jobs.py", line 106, in execute_job
    method(**kwargs)
  File "/opt/bench/erpnext/apps/frappe/frappe/core/doctype/user/user.py", line 994, in create_contact
    contact.insert(ignore_permissions=True, ignore_links=ignore_links, ignore_mandatory=ignore_mandatory)
  File "/opt/bench/erpnext/apps/frappe/frappe/model/document.py", line 229, in insert
    self._validate_links()
  File "/opt/bench/erpnext/apps/frappe/frappe/model/document.py", line 827, in _validate_links
  File "/opt/bench/erpnext/apps/frappe/frappe/__init__.py", line 443, in throw
    msgprint(msg, raise_exception=exc, title=title, indicator='red', is_minimizable=is_minimizable, wide=wide, as_list=as_list)
  File "/opt/bench/erpnext/apps/frappe/frappe/__init__.py", line 422, in msgprint
    _raise_exception()
  File "/opt/bench/erpnext/apps/frappe/frappe/__init__.py", line 376, in _raise_exception
    raise raise_exception(msg)
frappe.exceptions.LinkValidationError: Could not find User Id: huongttl@draco.biz

/opt/bench/erpnext/env/lib/python3.8/site-packages/openpyxl/worksheet/header_footer.py:48: UserWarning: Cannot parse header or footer so it will be ignored
  warn("""Cannot parse header or footer so it will be ignored""")
11:48:57 Traceback (most recent call last):
  File "/opt/bench/erpnext/env/lib/python3.8/site-packages/rq/worker.py", line 1013, in perform_job
    rv = job.perform()
  File "/opt/bench/erpnext/env/lib/python3.8/site-packages/rq/job.py", line 709, in perform
    self._result = self._execute()
  File "/opt/bench/erpnext/env/lib/python3.8/site-packages/rq/job.py", line 732, in _execute
    result = self.func(*self.args, **self.kwargs)
  File "/opt/bench/erpnext/apps/frappe/frappe/utils/background_jobs.py", line 106, in execute_job
    method(**kwargs)
  File "/opt/bench/erpnext/apps/frappe/frappe/core/doctype/user/user.py", line 994, in create_contact
    contact.insert(ignore_permissions=True, ignore_links=ignore_links, ignore_mandatory=ignore_mandatory)
  File "/opt/bench/erpnext/apps/frappe/frappe/model/document.py", line 229, in insert
    self._validate_links()
  File "/opt/bench/erpnext/apps/frappe/frappe/model/document.py", line 827, in _validate_links
  File "/opt/bench/erpnext/apps/frappe/frappe/__init__.py", line 443, in throw
    msgprint(msg, raise_exception=exc, title=title, indicator='red', is_minimizable=is_minimizable, wide=wide, as_list=as_list)
  File "/opt/bench/erpnext/apps/frappe/frappe/__init__.py", line 422, in msgprint
    _raise_exception()
  File "/opt/bench/erpnext/apps/frappe/frappe/__init__.py", line 376, in _raise_exception
    raise raise_exception(msg)
frappe.exceptions.LinkValidationError: Could not find User Id: trantn@draco.biz

11:57:11 Traceback (most recent call last):
  File "/opt/bench/erpnext/env/lib/python3.8/site-packages/rq/worker.py", line 1013, in perform_job
    rv = job.perform()
  File "/opt/bench/erpnext/env/lib/python3.8/site-packages/rq/job.py", line 709, in perform
    self._result = self._execute()
  File "/opt/bench/erpnext/env/lib/python3.8/site-packages/rq/job.py", line 732, in _execute
    result = self.func(*self.args, **self.kwargs)
  File "/opt/bench/erpnext/apps/frappe/frappe/utils/background_jobs.py", line 106, in execute_job
    method(**kwargs)
  File "/opt/bench/erpnext/apps/frappe/frappe/core/doctype/user/user.py", line 994, in create_contact
    contact.insert(ignore_permissions=True, ignore_links=ignore_links, ignore_mandatory=ignore_mandatory)
  File "/opt/bench/erpnext/apps/frappe/frappe/model/document.py", line 229, in insert
    self._validate_links()
  File "/opt/bench/erpnext/apps/frappe/frappe/model/document.py", line 827, in _validate_links
  File "/opt/bench/erpnext/apps/frappe/frappe/__init__.py", line 443, in throw
    msgprint(msg, raise_exception=exc, title=title, indicator='red', is_minimizable=is_minimizable, wide=wide, as_list=as_list)
  File "/opt/bench/erpnext/apps/frappe/frappe/__init__.py", line 422, in msgprint
    _raise_exception()
  File "/opt/bench/erpnext/apps/frappe/frappe/__init__.py", line 376, in _raise_exception
    raise raise_exception(msg)
frappe.exceptions.LinkValidationError: Could not find User Id: vanptc@draco.biz

15:51:47 Traceback (most recent call last):
  File "/opt/bench/erpnext/env/lib/python3.8/site-packages/rq/worker.py", line 1013, in perform_job
    rv = job.perform()
  File "/opt/bench/erpnext/env/lib/python3.8/site-packages/rq/job.py", line 709, in perform
    self._result = self._execute()
  File "/opt/bench/erpnext/env/lib/python3.8/site-packages/rq/job.py", line 732, in _execute
    result = self.func(*self.args, **self.kwargs)
  File "/opt/bench/erpnext/apps/frappe/frappe/utils/background_jobs.py", line 106, in execute_job
    method(**kwargs)
  File "/opt/bench/erpnext/apps/frappe/frappe/core/doctype/user/user.py", line 994, in create_contact
    contact.insert(ignore_permissions=True, ignore_links=ignore_links, ignore_mandatory=ignore_mandatory)
  File "/opt/bench/erpnext/apps/frappe/frappe/model/document.py", line 229, in insert
    self._validate_links()
  File "/opt/bench/erpnext/apps/frappe/frappe/model/document.py", line 827, in _validate_links
  File "/opt/bench/erpnext/apps/frappe/frappe/__init__.py", line 443, in throw
    msgprint(msg, raise_exception=exc, title=title, indicator='red', is_minimizable=is_minimizable, wide=wide, as_list=as_list)
  File "/opt/bench/erpnext/apps/frappe/frappe/__init__.py", line 422, in msgprint
    _raise_exception()
  File "/opt/bench/erpnext/apps/frappe/frappe/__init__.py", line 376, in _raise_exception
    raise raise_exception(msg)
frappe.exceptions.LinkValidationError: Could not find User Id: uren@gmail.com

15:29:27 Traceback (most recent call last):
  File "/opt/bench/erpnext/env/lib/python3.8/site-packages/rq/worker.py", line 1013, in perform_job
    rv = job.perform()
  File "/opt/bench/erpnext/env/lib/python3.8/site-packages/rq/job.py", line 709, in perform
    self._result = self._execute()
  File "/opt/bench/erpnext/env/lib/python3.8/site-packages/rq/job.py", line 732, in _execute
    result = self.func(*self.args, **self.kwargs)
  File "/opt/bench/erpnext/apps/frappe/frappe/utils/background_jobs.py", line 106, in execute_job
    method(**kwargs)
  File "/opt/bench/erpnext/apps/frappe/frappe/core/doctype/user/user.py", line 994, in create_contact
    contact.insert(ignore_permissions=True, ignore_links=ignore_links, ignore_mandatory=ignore_mandatory)
  File "/opt/bench/erpnext/apps/frappe/frappe/model/document.py", line 229, in insert
    self._validate_links()
  File "/opt/bench/erpnext/apps/frappe/frappe/model/document.py", line 827, in _validate_links
  File "/opt/bench/erpnext/apps/frappe/frappe/__init__.py", line 443, in throw
    msgprint(msg, raise_exception=exc, title=title, indicator='red', is_minimizable=is_minimizable, wide=wide, as_list=as_list)
  File "/opt/bench/erpnext/apps/frappe/frappe/__init__.py", line 422, in msgprint
    _raise_exception()
  File "/opt/bench/erpnext/apps/frappe/frappe/__init__.py", line 376, in _raise_exception
    raise raise_exception(msg)
frappe.exceptions.LinkValidationError: Could not find User Id: phuoc@mobile.biz

15:38:07 Traceback (most recent call last):
  File "/opt/bench/erpnext/env/lib/python3.8/site-packages/rq/worker.py", line 1013, in perform_job
    rv = job.perform()
  File "/opt/bench/erpnext/env/lib/python3.8/site-packages/rq/job.py", line 709, in perform
    self._result = self._execute()
  File "/opt/bench/erpnext/env/lib/python3.8/site-packages/rq/job.py", line 732, in _execute
    result = self.func(*self.args, **self.kwargs)
  File "/opt/bench/erpnext/apps/frappe/frappe/utils/background_jobs.py", line 106, in execute_job
    method(**kwargs)
  File "/opt/bench/erpnext/apps/frappe/frappe/core/doctype/user/user.py", line 994, in create_contact
    contact.insert(ignore_permissions=True, ignore_links=ignore_links, ignore_mandatory=ignore_mandatory)
  File "/opt/bench/erpnext/apps/frappe/frappe/model/document.py", line 229, in insert
    self._validate_links()
  File "/opt/bench/erpnext/apps/frappe/frappe/model/document.py", line 827, in _validate_links
  File "/opt/bench/erpnext/apps/frappe/frappe/__init__.py", line 443, in throw
    msgprint(msg, raise_exception=exc, title=title, indicator='red', is_minimizable=is_minimizable, wide=wide, as_list=as_list)
  File "/opt/bench/erpnext/apps/frappe/frappe/__init__.py", line 422, in msgprint
    _raise_exception()
  File "/opt/bench/erpnext/apps/frappe/frappe/__init__.py", line 376, in _raise_exception
    raise raise_exception(msg)
frappe.exceptions.LinkValidationError: Could not find User Id: liem@mobile.biz

15:45:50 Traceback (most recent call last):
  File "/opt/bench/erpnext/env/lib/python3.8/site-packages/rq/worker.py", line 1013, in perform_job
    rv = job.perform()
  File "/opt/bench/erpnext/env/lib/python3.8/site-packages/rq/job.py", line 709, in perform
    self._result = self._execute()
  File "/opt/bench/erpnext/env/lib/python3.8/site-packages/rq/job.py", line 732, in _execute
    result = self.func(*self.args, **self.kwargs)
  File "/opt/bench/erpnext/apps/frappe/frappe/utils/background_jobs.py", line 106, in execute_job
    method(**kwargs)
  File "/opt/bench/erpnext/apps/frappe/frappe/core/doctype/user/user.py", line 994, in create_contact
    contact.insert(ignore_permissions=True, ignore_links=ignore_links, ignore_mandatory=ignore_mandatory)
  File "/opt/bench/erpnext/apps/frappe/frappe/model/document.py", line 229, in insert
    self._validate_links()
  File "/opt/bench/erpnext/apps/frappe/frappe/model/document.py", line 827, in _validate_links
  File "/opt/bench/erpnext/apps/frappe/frappe/__init__.py", line 443, in throw
    msgprint(msg, raise_exception=exc, title=title, indicator='red', is_minimizable=is_minimizable, wide=wide, as_list=as_list)
  File "/opt/bench/erpnext/apps/frappe/frappe/__init__.py", line 422, in msgprint
    _raise_exception()
  File "/opt/bench/erpnext/apps/frappe/frappe/__init__.py", line 376, in _raise_exception
    raise raise_exception(msg)
frappe.exceptions.LinkValidationError: Could not find User Id: tuanla@mobile.biz

16:15:14 Traceback (most recent call last):
  File "/opt/bench/erpnext/env/lib/python3.8/site-packages/rq/worker.py", line 1013, in perform_job
    rv = job.perform()
  File "/opt/bench/erpnext/env/lib/python3.8/site-packages/rq/job.py", line 709, in perform
    self._result = self._execute()
  File "/opt/bench/erpnext/env/lib/python3.8/site-packages/rq/job.py", line 732, in _execute
    result = self.func(*self.args, **self.kwargs)
  File "/opt/bench/erpnext/apps/frappe/frappe/utils/background_jobs.py", line 106, in execute_job
    method(**kwargs)
  File "/opt/bench/erpnext/apps/frappe/frappe/core/doctype/user/user.py", line 994, in create_contact
    contact.insert(ignore_permissions=True, ignore_links=ignore_links, ignore_mandatory=ignore_mandatory)
  File "/opt/bench/erpnext/apps/frappe/frappe/model/document.py", line 229, in insert
    self._validate_links()
  File "/opt/bench/erpnext/apps/frappe/frappe/model/document.py", line 827, in _validate_links
  File "/opt/bench/erpnext/apps/frappe/frappe/__init__.py", line 443, in throw
    msgprint(msg, raise_exception=exc, title=title, indicator='red', is_minimizable=is_minimizable, wide=wide, as_list=as_list)
  File "/opt/bench/erpnext/apps/frappe/frappe/__init__.py", line 422, in msgprint
    _raise_exception()
  File "/opt/bench/erpnext/apps/frappe/frappe/__init__.py", line 376, in _raise_exception
    raise raise_exception(msg)
frappe.exceptions.LinkValidationError: Could not find User Id: tai@mobile.biz

16:03:12 Traceback (most recent call last):
  File "/opt/bench/erpnext/env/lib/python3.8/site-packages/rq/worker.py", line 1013, in perform_job
    rv = job.perform()
  File "/opt/bench/erpnext/env/lib/python3.8/site-packages/rq/job.py", line 709, in perform
    self._result = self._execute()
  File "/opt/bench/erpnext/env/lib/python3.8/site-packages/rq/job.py", line 732, in _execute
    result = self.func(*self.args, **self.kwargs)
  File "/opt/bench/erpnext/apps/frappe/frappe/utils/background_jobs.py", line 106, in execute_job
    method(**kwargs)
  File "/opt/bench/erpnext/apps/erpnext/erpnext/payroll/doctype/salary_structure/salary_structure.py", line 120, in assign_salary_structure_for_employees
    salary_structures_assignment = create_salary_structures_assignment(employee,
  File "/opt/bench/erpnext/apps/erpnext/erpnext/payroll/doctype/salary_structure/salary_structure.py", line 149, in create_salary_structures_assignment
    assignment.save(ignore_permissions = True)
  File "/opt/bench/erpnext/apps/frappe/frappe/model/document.py", line 282, in save
    return self._save(*args, **kwargs)
  File "/opt/bench/erpnext/apps/frappe/frappe/model/document.py", line 304, in _save
    self.insert()
  File "/opt/bench/erpnext/apps/frappe/frappe/model/document.py", line 235, in insert
    self.run_before_save_methods()
  File "/opt/bench/erpnext/apps/frappe/frappe/model/document.py", line 965, in run_before_save_methods
    self.run_method("validate")
  File "/opt/bench/erpnext/apps/frappe/frappe/model/document.py", line 859, in run_method
    fn = lambda self, *args, **kwargs: None
  File "/opt/bench/erpnext/apps/frappe/frappe/model/document.py", line 1155, in composer
    return composed(self, method, *args, **kwargs)
  File "/opt/bench/erpnext/apps/frappe/frappe/model/document.py", line 1138, in runner
    add_to_return_value(self, fn(self, *args, **kwargs))
  File "/opt/bench/erpnext/apps/frappe/frappe/model/document.py", line 853, in <lambda>
    del kwargs["flags"]
  File "/opt/bench/erpnext/apps/erpnext/erpnext/payroll/doctype/salary_structure_assignment/salary_structure_assignment.py", line 15, in validate
    self.validate_dates()
  File "/opt/bench/erpnext/apps/erpnext/erpnext/payroll/doctype/salary_structure_assignment/salary_structure_assignment.py", line 25, in validate_dates
    frappe.throw(_("Salary Structure Assignment for Employee already exists"), DuplicateAssignment)
  File "/opt/bench/erpnext/apps/frappe/frappe/__init__.py", line 443, in throw
    msgprint(msg, raise_exception=exc, title=title, indicator='red', is_minimizable=is_minimizable, wide=wide, as_list=as_list)
  File "/opt/bench/erpnext/apps/frappe/frappe/__init__.py", line 422, in msgprint
    _raise_exception()
  File "/opt/bench/erpnext/apps/frappe/frappe/__init__.py", line 376, in _raise_exception
    raise raise_exception(msg)
erpnext.payroll.doctype.salary_structure_assignment.salary_structure_assignment.DuplicateAssignment: Salary Structure Assignment for Employee already exists

11:39:04 Traceback (most recent call last):
  File "/opt/bench/erpnext/env/lib/python3.8/site-packages/rq/worker.py", line 1013, in perform_job
    rv = job.perform()
  File "/opt/bench/erpnext/env/lib/python3.8/site-packages/rq/job.py", line 709, in perform
    self._result = self._execute()
  File "/opt/bench/erpnext/env/lib/python3.8/site-packages/rq/job.py", line 732, in _execute
    result = self.func(*self.args, **self.kwargs)
  File "/opt/bench/erpnext/apps/frappe/frappe/utils/background_jobs.py", line 106, in execute_job
    method(**kwargs)
  File "/opt/bench/erpnext/apps/frappe/frappe/core/doctype/user/user.py", line 994, in create_contact
    contact.insert(ignore_permissions=True, ignore_links=ignore_links, ignore_mandatory=ignore_mandatory)
  File "/opt/bench/erpnext/apps/frappe/frappe/model/document.py", line 229, in insert
    self._validate_links()
  File "/opt/bench/erpnext/apps/frappe/frappe/model/document.py", line 827, in _validate_links
  File "/opt/bench/erpnext/apps/frappe/frappe/__init__.py", line 443, in throw
    msgprint(msg, raise_exception=exc, title=title, indicator='red', is_minimizable=is_minimizable, wide=wide, as_list=as_list)
  File "/opt/bench/erpnext/apps/frappe/frappe/__init__.py", line 422, in msgprint
    _raise_exception()
  File "/opt/bench/erpnext/apps/frappe/frappe/__init__.py", line 376, in _raise_exception
    raise raise_exception(msg)
frappe.exceptions.LinkValidationError: Could not find User Id: phuonght@draco.biz

15:06:51 Traceback (most recent call last):
  File "/opt/bench/erpnext/env/lib/python3.8/site-packages/rq/worker.py", line 1013, in perform_job
    rv = job.perform()
  File "/opt/bench/erpnext/env/lib/python3.8/site-packages/rq/job.py", line 709, in perform
    self._result = self._execute()
  File "/opt/bench/erpnext/env/lib/python3.8/site-packages/rq/job.py", line 732, in _execute
    result = self.func(*self.args, **self.kwargs)
  File "/opt/bench/erpnext/apps/frappe/frappe/utils/background_jobs.py", line 106, in execute_job
    method(**kwargs)
  File "/opt/bench/erpnext/apps/frappe/frappe/core/doctype/user/user.py", line 994, in create_contact
    contact.insert(ignore_permissions=True, ignore_links=ignore_links, ignore_mandatory=ignore_mandatory)
  File "/opt/bench/erpnext/apps/frappe/frappe/model/document.py", line 229, in insert
    self._validate_links()
  File "/opt/bench/erpnext/apps/frappe/frappe/model/document.py", line 827, in _validate_links
  File "/opt/bench/erpnext/apps/frappe/frappe/__init__.py", line 443, in throw
    msgprint(msg, raise_exception=exc, title=title, indicator='red', is_minimizable=is_minimizable, wide=wide, as_list=as_list)
  File "/opt/bench/erpnext/apps/frappe/frappe/__init__.py", line 422, in msgprint
    _raise_exception()
  File "/opt/bench/erpnext/apps/frappe/frappe/__init__.py", line 376, in _raise_exception
    raise raise_exception(msg)
frappe.exceptions.LinkValidationError: Could not find User Id: trantn1@draco.biz

15:22:13 Traceback (most recent call last):
  File "/opt/bench/erpnext/env/lib/python3.8/site-packages/rq/worker.py", line 1013, in perform_job
    rv = job.perform()
  File "/opt/bench/erpnext/env/lib/python3.8/site-packages/rq/job.py", line 709, in perform
    self._result = self._execute()
  File "/opt/bench/erpnext/env/lib/python3.8/site-packages/rq/job.py", line 732, in _execute
    result = self.func(*self.args, **self.kwargs)
  File "/opt/bench/erpnext/apps/frappe/frappe/utils/background_jobs.py", line 106, in execute_job
    method(**kwargs)
  File "/opt/bench/erpnext/apps/frappe/frappe/core/doctype/user/user.py", line 994, in create_contact
    contact.insert(ignore_permissions=True, ignore_links=ignore_links, ignore_mandatory=ignore_mandatory)
  File "/opt/bench/erpnext/apps/frappe/frappe/model/document.py", line 229, in insert
    self._validate_links()
  File "/opt/bench/erpnext/apps/frappe/frappe/model/document.py", line 827, in _validate_links
  File "/opt/bench/erpnext/apps/frappe/frappe/__init__.py", line 443, in throw
    msgprint(msg, raise_exception=exc, title=title, indicator='red', is_minimizable=is_minimizable, wide=wide, as_list=as_list)
  File "/opt/bench/erpnext/apps/frappe/frappe/__init__.py", line 422, in msgprint
    _raise_exception()
  File "/opt/bench/erpnext/apps/frappe/frappe/__init__.py", line 376, in _raise_exception
    raise raise_exception(msg)
frappe.exceptions.LinkValidationError: Could not find User Id: vanptc1@draco.biz

15:25:45 Traceback (most recent call last):
  File "/opt/bench/erpnext/env/lib/python3.8/site-packages/rq/worker.py", line 1013, in perform_job
    rv = job.perform()
  File "/opt/bench/erpnext/env/lib/python3.8/site-packages/rq/job.py", line 709, in perform
    self._result = self._execute()
  File "/opt/bench/erpnext/env/lib/python3.8/site-packages/rq/job.py", line 732, in _execute
    result = self.func(*self.args, **self.kwargs)
  File "/opt/bench/erpnext/apps/frappe/frappe/utils/background_jobs.py", line 106, in execute_job
    method(**kwargs)
  File "/opt/bench/erpnext/apps/frappe/frappe/core/doctype/user/user.py", line 994, in create_contact
    contact.insert(ignore_permissions=True, ignore_links=ignore_links, ignore_mandatory=ignore_mandatory)
  File "/opt/bench/erpnext/apps/frappe/frappe/model/document.py", line 229, in insert
    self._validate_links()
  File "/opt/bench/erpnext/apps/frappe/frappe/model/document.py", line 827, in _validate_links
  File "/opt/bench/erpnext/apps/frappe/frappe/__init__.py", line 443, in throw
    msgprint(msg, raise_exception=exc, title=title, indicator='red', is_minimizable=is_minimizable, wide=wide, as_list=as_list)
  File "/opt/bench/erpnext/apps/frappe/frappe/__init__.py", line 422, in msgprint
    _raise_exception()
  File "/opt/bench/erpnext/apps/frappe/frappe/__init__.py", line 376, in _raise_exception
    raise raise_exception(msg)
frappe.exceptions.LinkValidationError: Could not find User Id: duyenlt1@draco.biz

15:26:30 Traceback (most recent call last):
  File "/opt/bench/erpnext/env/lib/python3.8/site-packages/rq/worker.py", line 1013, in perform_job
    rv = job.perform()
  File "/opt/bench/erpnext/env/lib/python3.8/site-packages/rq/job.py", line 709, in perform
    self._result = self._execute()
  File "/opt/bench/erpnext/env/lib/python3.8/site-packages/rq/job.py", line 732, in _execute
    result = self.func(*self.args, **self.kwargs)
  File "/opt/bench/erpnext/apps/frappe/frappe/utils/background_jobs.py", line 106, in execute_job
    method(**kwargs)
  File "/opt/bench/erpnext/apps/frappe/frappe/core/doctype/user/user.py", line 994, in create_contact
    contact.insert(ignore_permissions=True, ignore_links=ignore_links, ignore_mandatory=ignore_mandatory)
  File "/opt/bench/erpnext/apps/frappe/frappe/model/document.py", line 229, in insert
    self._validate_links()
  File "/opt/bench/erpnext/apps/frappe/frappe/model/document.py", line 827, in _validate_links
  File "/opt/bench/erpnext/apps/frappe/frappe/__init__.py", line 443, in throw
    msgprint(msg, raise_exception=exc, title=title, indicator='red', is_minimizable=is_minimizable, wide=wide, as_list=as_list)
  File "/opt/bench/erpnext/apps/frappe/frappe/__init__.py", line 422, in msgprint
    _raise_exception()
  File "/opt/bench/erpnext/apps/frappe/frappe/__init__.py", line 376, in _raise_exception
    raise raise_exception(msg)
frappe.exceptions.LinkValidationError: Could not find User Id: thuonghu305@mail.com

15:42:25 Traceback (most recent call last):
  File "/opt/bench/erpnext/env/lib/python3.8/site-packages/rq/worker.py", line 1013, in perform_job
    rv = job.perform()
  File "/opt/bench/erpnext/env/lib/python3.8/site-packages/rq/job.py", line 709, in perform
    self._result = self._execute()
  File "/opt/bench/erpnext/env/lib/python3.8/site-packages/rq/job.py", line 732, in _execute
    result = self.func(*self.args, **self.kwargs)
  File "/opt/bench/erpnext/apps/frappe/frappe/utils/background_jobs.py", line 106, in execute_job
    method(**kwargs)
  File "/opt/bench/erpnext/apps/frappe/frappe/core/doctype/user/user.py", line 994, in create_contact
    contact.insert(ignore_permissions=True, ignore_links=ignore_links, ignore_mandatory=ignore_mandatory)
  File "/opt/bench/erpnext/apps/frappe/frappe/model/document.py", line 229, in insert
    self._validate_links()
  File "/opt/bench/erpnext/apps/frappe/frappe/model/document.py", line 827, in _validate_links
  File "/opt/bench/erpnext/apps/frappe/frappe/__init__.py", line 443, in throw
    msgprint(msg, raise_exception=exc, title=title, indicator='red', is_minimizable=is_minimizable, wide=wide, as_list=as_list)
  File "/opt/bench/erpnext/apps/frappe/frappe/__init__.py", line 422, in msgprint
    _raise_exception()
  File "/opt/bench/erpnext/apps/frappe/frappe/__init__.py", line 376, in _raise_exception
    raise raise_exception(msg)
frappe.exceptions.LinkValidationError: Could not find User Id: phuonght1@draco.biz

11:11:29 Traceback (most recent call last):
  File "/opt/bench/erpnext/env/lib/python3.8/site-packages/rq/worker.py", line 1013, in perform_job
    rv = job.perform()
  File "/opt/bench/erpnext/env/lib/python3.8/site-packages/rq/job.py", line 709, in perform
    self._result = self._execute()
  File "/opt/bench/erpnext/env/lib/python3.8/site-packages/rq/job.py", line 732, in _execute
    result = self.func(*self.args, **self.kwargs)
  File "/opt/bench/erpnext/apps/frappe/frappe/utils/background_jobs.py", line 106, in execute_job
    method(**kwargs)
  File "/opt/bench/erpnext/apps/frappe/frappe/core/doctype/user/user.py", line 994, in create_contact
    contact.insert(ignore_permissions=True, ignore_links=ignore_links, ignore_mandatory=ignore_mandatory)
  File "/opt/bench/erpnext/apps/frappe/frappe/model/document.py", line 229, in insert
    self._validate_links()
  File "/opt/bench/erpnext/apps/frappe/frappe/model/document.py", line 827, in _validate_links
  File "/opt/bench/erpnext/apps/frappe/frappe/__init__.py", line 443, in throw
    msgprint(msg, raise_exception=exc, title=title, indicator='red', is_minimizable=is_minimizable, wide=wide, as_list=as_list)
  File "/opt/bench/erpnext/apps/frappe/frappe/__init__.py", line 422, in msgprint
    _raise_exception()
  File "/opt/bench/erpnext/apps/frappe/frappe/__init__.py", line 376, in _raise_exception
    raise raise_exception(msg)
frappe.exceptions.LinkValidationError: Could not find User Id: test@draco.biz

11:27:08 Traceback (most recent call last):
  File "/opt/bench/erpnext/env/lib/python3.8/site-packages/rq/worker.py", line 1013, in perform_job
    rv = job.perform()
  File "/opt/bench/erpnext/env/lib/python3.8/site-packages/rq/job.py", line 709, in perform
    self._result = self._execute()
  File "/opt/bench/erpnext/env/lib/python3.8/site-packages/rq/job.py", line 732, in _execute
    result = self.func(*self.args, **self.kwargs)
  File "/opt/bench/erpnext/apps/frappe/frappe/utils/background_jobs.py", line 106, in execute_job
    method(**kwargs)
  File "/opt/bench/erpnext/apps/frappe/frappe/core/doctype/user/user.py", line 994, in create_contact
    contact.insert(ignore_permissions=True, ignore_links=ignore_links, ignore_mandatory=ignore_mandatory)
  File "/opt/bench/erpnext/apps/frappe/frappe/model/document.py", line 229, in insert
    self._validate_links()
  File "/opt/bench/erpnext/apps/frappe/frappe/model/document.py", line 827, in _validate_links
  File "/opt/bench/erpnext/apps/frappe/frappe/__init__.py", line 443, in throw
    msgprint(msg, raise_exception=exc, title=title, indicator='red', is_minimizable=is_minimizable, wide=wide, as_list=as_list)
  File "/opt/bench/erpnext/apps/frappe/frappe/__init__.py", line 422, in msgprint
    _raise_exception()
  File "/opt/bench/erpnext/apps/frappe/frappe/__init__.py", line 376, in _raise_exception
    raise raise_exception(msg)
frappe.exceptions.LinkValidationError: Could not find User Id: test1@draco.biz

11:50:50 Traceback (most recent call last):
  File "/opt/bench/erpnext/env/lib/python3.8/site-packages/rq/worker.py", line 1013, in perform_job
    rv = job.perform()
  File "/opt/bench/erpnext/env/lib/python3.8/site-packages/rq/job.py", line 709, in perform
    self._result = self._execute()
  File "/opt/bench/erpnext/env/lib/python3.8/site-packages/rq/job.py", line 732, in _execute
    result = self.func(*self.args, **self.kwargs)
  File "/opt/bench/erpnext/apps/frappe/frappe/utils/background_jobs.py", line 106, in execute_job
    method(**kwargs)
  File "/opt/bench/erpnext/apps/frappe/frappe/core/doctype/user/user.py", line 994, in create_contact
    contact.insert(ignore_permissions=True, ignore_links=ignore_links, ignore_mandatory=ignore_mandatory)
  File "/opt/bench/erpnext/apps/frappe/frappe/model/document.py", line 229, in insert
    self._validate_links()
  File "/opt/bench/erpnext/apps/frappe/frappe/model/document.py", line 827, in _validate_links
  File "/opt/bench/erpnext/apps/frappe/frappe/__init__.py", line 443, in throw
    msgprint(msg, raise_exception=exc, title=title, indicator='red', is_minimizable=is_minimizable, wide=wide, as_list=as_list)
  File "/opt/bench/erpnext/apps/frappe/frappe/__init__.py", line 422, in msgprint
    _raise_exception()
  File "/opt/bench/erpnext/apps/frappe/frappe/__init__.py", line 376, in _raise_exception
    raise raise_exception(msg)
frappe.exceptions.LinkValidationError: Could not find User Id: test1@draco.biz

10:10:55 Traceback (most recent call last):
  File "/opt/bench/erpnext/env/lib/python3.8/site-packages/rq/worker.py", line 1013, in perform_job
    rv = job.perform()
  File "/opt/bench/erpnext/env/lib/python3.8/site-packages/rq/job.py", line 709, in perform
    self._result = self._execute()
  File "/opt/bench/erpnext/env/lib/python3.8/site-packages/rq/job.py", line 732, in _execute
    result = self.func(*self.args, **self.kwargs)
  File "/opt/bench/erpnext/apps/frappe/frappe/utils/background_jobs.py", line 106, in execute_job
    method(**kwargs)
  File "/opt/bench/erpnext/apps/frappe/frappe/core/doctype/user/user.py", line 994, in create_contact
    contact.insert(ignore_permissions=True, ignore_links=ignore_links, ignore_mandatory=ignore_mandatory)
  File "/opt/bench/erpnext/apps/frappe/frappe/model/document.py", line 229, in insert
    self._validate_links()
  File "/opt/bench/erpnext/apps/frappe/frappe/model/document.py", line 827, in _validate_links
  File "/opt/bench/erpnext/apps/frappe/frappe/__init__.py", line 443, in throw
    msgprint(msg, raise_exception=exc, title=title, indicator='red', is_minimizable=is_minimizable, wide=wide, as_list=as_list)
  File "/opt/bench/erpnext/apps/frappe/frappe/__init__.py", line 422, in msgprint
    _raise_exception()
  File "/opt/bench/erpnext/apps/frappe/frappe/__init__.py", line 376, in _raise_exception
    raise raise_exception(msg)
frappe.exceptions.LinkValidationError: Could not find User Id: phucpd@mobile.biz

10:29:32 Traceback (most recent call last):
  File "/opt/bench/erpnext/env/lib/python3.8/site-packages/rq/worker.py", line 1013, in perform_job
    rv = job.perform()
  File "/opt/bench/erpnext/env/lib/python3.8/site-packages/rq/job.py", line 709, in perform
    self._result = self._execute()
  File "/opt/bench/erpnext/env/lib/python3.8/site-packages/rq/job.py", line 732, in _execute
    result = self.func(*self.args, **self.kwargs)
  File "/opt/bench/erpnext/apps/frappe/frappe/utils/background_jobs.py", line 106, in execute_job
    method(**kwargs)
  File "/opt/bench/erpnext/apps/frappe/frappe/core/doctype/user/user.py", line 994, in create_contact
    contact.insert(ignore_permissions=True, ignore_links=ignore_links, ignore_mandatory=ignore_mandatory)
  File "/opt/bench/erpnext/apps/frappe/frappe/model/document.py", line 229, in insert
    self._validate_links()
  File "/opt/bench/erpnext/apps/frappe/frappe/model/document.py", line 827, in _validate_links
  File "/opt/bench/erpnext/apps/frappe/frappe/__init__.py", line 443, in throw
    msgprint(msg, raise_exception=exc, title=title, indicator='red', is_minimizable=is_minimizable, wide=wide, as_list=as_list)
  File "/opt/bench/erpnext/apps/frappe/frappe/__init__.py", line 422, in msgprint
    _raise_exception()
  File "/opt/bench/erpnext/apps/frappe/frappe/__init__.py", line 376, in _raise_exception
    raise raise_exception(msg)
frappe.exceptions.LinkValidationError: Could not find User Id: thunta@draco.biz

15:23:16 Traceback (most recent call last):
  File "/opt/bench/erpnext/env/lib/python3.8/site-packages/rq/worker.py", line 1013, in perform_job
    rv = job.perform()
  File "/opt/bench/erpnext/env/lib/python3.8/site-packages/rq/job.py", line 709, in perform
    self._result = self._execute()
  File "/opt/bench/erpnext/env/lib/python3.8/site-packages/rq/job.py", line 732, in _execute
    result = self.func(*self.args, **self.kwargs)
  File "/opt/bench/erpnext/apps/frappe/frappe/utils/background_jobs.py", line 106, in execute_job
    method(**kwargs)
  File "/opt/bench/erpnext/apps/frappe/frappe/core/doctype/user/user.py", line 994, in create_contact
    contact.insert(ignore_permissions=True, ignore_links=ignore_links, ignore_mandatory=ignore_mandatory)
  File "/opt/bench/erpnext/apps/frappe/frappe/model/document.py", line 229, in insert
    self._validate_links()
  File "/opt/bench/erpnext/apps/frappe/frappe/model/document.py", line 827, in _validate_links
  File "/opt/bench/erpnext/apps/frappe/frappe/__init__.py", line 443, in throw
    msgprint(msg, raise_exception=exc, title=title, indicator='red', is_minimizable=is_minimizable, wide=wide, as_list=as_list)
  File "/opt/bench/erpnext/apps/frappe/frappe/__init__.py", line 422, in msgprint
    _raise_exception()
  File "/opt/bench/erpnext/apps/frappe/frappe/__init__.py", line 376, in _raise_exception
    raise raise_exception(msg)
frappe.exceptions.LinkValidationError: Could not find User Id: thunta@mobile.biz

